Workbook
Name Access: [1]Validation!$E$2:$E$223
Name AccessCircuit: [1]Validation!$C$2:$C$29
Name ACTION: #REF!
Name CoS: [1]Validation!$G$2:$G$47
Name Countries: [1]Validation!$A$2:$A$301
Name DSLCheckService: [1]Validation!$H$2:$H$4
Name Port: [1]Validation!$F$2:$F$40
Name VancoProducts: [1]Validation!$B$2:$B$4

Sheet Cover
B2: TEST CASE
B3: Version: | C3: 1
B4: Issue date: | C4: 16/03/2025
B6: Project Name: | C6: Quản Lý Khóa Học
B7: Project Code: | C7: CMS_18
B10: Record of change:
B11: Effective Date | C11: Version | D11: Change location | E11: Change description | F11: Originator | G11: Reviewer/ Approver | H11: Reference
B12: 21/03/2025 | C12: v1.0.0 | D12: Module Regiser | E12: Thêm 4 test case cho tính năng Đăng kí | F12: Cẩm Tú | G12: Thành Nhật | H12: REG - User Registration
B13: 21/03/2025 | C13: v1.0.0 | D13: Module Login | E13: Thêm 2 test case cho tính năng Đăng nhập | F13: Cẩm Tú | G13: Thành Nhật | H13: AUTH - User Login
B14: 28/03/2025 | C14: v1.0.1 | D14: Module Regiser | E14: Test lại 2 test case fail | F14: Cẩm Tú | G14: Thành Nhật | H14: REG - User Registration
B15: 28/03/2025 | C15: v1.0.1 | D15: Module Login | E15: Test lại 1 test case fail | F15: Cẩm Tú | G15: Thành Nhật | H15: AUTH - User Login
B16: 28/03/2025 | C16: v1.1.0 | D16: Module Login | E16: Thêm 2 test case cho tính năng Quên mật khẩu | F16: Cẩm Tú | G16: Thành Nhật | H16: AUTH - User Login
B17: 45661 | C17: v1.1.0 | D17: Module Login | E17: Thêm 1 test case cho tính năng Quên mật khẩu | F17: Cẩm Tú | G17: Thành Nhật | H17: AUTH - User Login
B18: 45720 | C18: v1.1.1 | D18: Module Regiser | E18: Test lại 1 test case fail | F18: Cẩm Tú | G18: Thành Nhật | H18: REG - User Registration
B19: 45720 | C19: v1.1.1 | D19: Module Login | E19: Test lại 2 test case fail | F19: Cẩm Tú | G19: Thành Nhật | H19: AUTH - User Login
B20: 45995 | C20: v1.2.0 | D20: Module CourseManagement | E20: Thêm 4 test case cho tính năng Quản lý khóa học | F20: Cẩm Tú | G20: Thành Nhật | H20: COURSE - Course Management
B21: 21/04/2025 | C21: v1.3.0 | D21: Module CourseManagement | E21: Test lại 3 test case fail | F21: Cẩm Tú | G21: Thành Nhật | H21: COURSE - Course Management
B22: 21/04/2025 | C22: v1.3.0 | D22: Module CourseManagement | E22: Thêm 6 test case cho tính năng Quản lý khóa học | F22: Cẩm Tú | G22: Thành Nhật | H22: COURSE - Course Management
B23: 21/04/2025 | C23: v1.3.0 | D23: Module FeeManagement | E23: Thêm 2 test case cho tính năng Quản lý thanh toán | F23: Cẩm Tú | G23: Thành Nhật Hữu Nguyện | H23: FEE - Fee Management
B24: 21/04/2025 | C24: v1.3.0 | D24: Module Admin | E24: Thêm 5 test case cho tính năng Admin | F24: Cẩm Tú | G24: Thành Nhật | H24: ADMIN - Administration Module
B25: 25/04/2025 | C25: v1.3.0 | D25: Module Login | E25: Test lại 1 test case fail | F25: Cẩm Tú | G25: Thành Nhật | H25: AUTH - User Login
B26: 26/04/2025 | C26: v1.4.0 | D26: Module CourseManagement | E26: Thêm 5 test case cho tính năng Quản lý khóa học | F26: Cẩm Tú | G26: Thành Nhật | H26: COURSE - Course Management
B27: 26/04/2025 | C27: v1.4.0 | D27: Module FeeManagement | E27: Thêm 2 test case cho tính năng Quản lý thanh toán | F27: Cẩm Tú | G27: Thành Nhật Hữu Nguyện | H27: FEE - Fee Management
B28: 27/04/2025 | C28: v1.5.0 | D28: Module CourseManagement | E28: Thêm 12 test case cho tính năng Quản lý khóa học | F28: Cẩm Tú | G28: Thành Nhật Hữu Nguyện | H28: COURSE - Course Management
B29: 27/04/2025 | C29: v1.5.0 | D29: Module FeeManagement | E29: Thêm 1 test case cho tính năng Quản lý thanh toán | F29: Cẩm Tú | G29: Thành Nhật Hữu Nguyện | H29: FEE - Fee Management

Sheet Module Register
A1: TEST CASE
A3: System Name： | B3: Course Management System
A4: Module Code： | B4: REG - User Registration
A5: Test requirement: | B5: REQ0 - Functional Testing for Registration
A6: Pass | B6: =COUNTIF(I:I,"Pass") -> 4 | C6: Pending | D6: =COUNTIF(I:I,"Pending") -> 0
A7: Fail | B7: =COUNTIF(I:I,"Fail") -> 0 | C7: Number of test cases: | D7: =COUNTIF(A:A, "TC*") -> 4
A9: ID | B9: Test Case Description | C9: Test Case Procedure | D9: Expected Output | H9: Test date | I9: Result | J9: Note
A12: 1. Kiểm tra lỗi nhập mật khẩu có khoảng trắng
A13: TC1 | B13: Test case dùng để kiểm thử chức năng Đăng kí tài khoản cho học viên khi người dùng nhập mật khẩu chứa khoảng trắng ' ' | C13: 1: Nhập thông tin tên và email hợp lệ 2: Nhập mật khẩu khớp nhau và đúng yêu cầu độ dài, ký tự nhưng có chứa khoảng trắng ' ' 3: Nhấn nút 'Đăng ký' | D13: Hiển thị cảnh báo lỗi "Mật khẩu phải từ 8-16 ký tự, có chữ hoa, chữ thường, số và ký tự đặc biệt." | H13: 21/03/2025 | I13: Fail lần 1
H14: 28/03/2025 | I14: Fail lần 2
H15: 45720 | I15: Pass
A16: 2. Kiểm tra lỗi nhập email không có thật
A17: TC2 | B17: Test case dùng để kiểm thử chức năng Đăng kí tài khoản cho học viên khi người dùng nhập sai định dạng email - email không tồn tại | C17: 1: Nhập thông tin tên và mật khẩu hợp lệ 2: Nhập email giả định dạng "nguyenvana@1.2" 3: Nhấn nút 'Đăng ký' | D17: Hiển thị cảnh báo lỗi "Email không hợp lệ." | H17: 21/03/2025 | I17: Fail lần 1 | J17: #VALUE!
H18: 28/03/2025 | I18: Pass | J18: #VALUE!
A19: 3. Kiểm tra mã hóa mật khẩu khi đăng ký nhiều tài khoản cùng mật khẩu
A20: TC3 | B20: Test case dùng để kiểm thử bảo mật Đăng kí tài khoản cho học viên khi nhiều người dùng đăng kí cùng 1 mật khẩu | C20: 1: Nhập thông tin tạo 1 tài khoản hợp lệ 2: Nhập thông tin tạo 1 tài khoản hợp lệ khác với mật khẩu trùng khớp với tài khoản vừa tạo 3: Nhấn nút 'Đăng ký' 4: Sau khi đăng ký thành công vào database bảng 'nguoidung' để kiểm tra cột 'mat_khau' | D20: Mật khẩu 2 tài khoản đã được băm thành 2 đoạn mã khác nhau | H20: 21/03/2025 | I20: Pass | J20: #VALUE!
A21: 4. Kiểm tra mã hóa mật khẩu khi đăng ký nhiều tài khoản cùng mật khẩu
A22: TC4 | B22: Test case dùng để kiểm thử bảo mật Đăng kí tài khoản cho học viên khi nhiều người dùng đăng kí cùng 1 mật khẩu | C22: 1: Nhập thông tin tạo 1 tài khoản hợp lệ 2: Nhập thông tin tạo 1 tài khoản hợp lệ khác với mật khẩu trùng khớp với tài khoản vừa tạo 3: Nhấn nút 'Đăng ký' 4: Sau khi đăng ký thành công vào database bảng 'nguoidung' để kiểm tra cột 'mat_khau' | D22: Hiển thị thông báo lỗi với yêu cầu nhập lại | H22: 21/03/2025 | I22: Pass | J22: #VALUE! | K22: Note: Nên có hiển thị rõ lỗi người dùng bị là gì và yêu cầu nhập lại

Sheet Module Login
A1: TEST CASE
A3: System Name： | B3: Course Management System
A4: Module Code： | B4: AUTH - User Login
A5: Test requirement: | B5: REQ0 - Functional Testing for Login
A6: Pass | B6: =COUNTIF(I:I,"Pass") -> 5 | C6: Pending | D6: =COUNTIF(I:I,"Pending") -> 0
A7: Fail | B7: =COUNTIF(I:I,"Fail") -> 0 | C7: Number of test cases: | D7: =COUNTIF(A:A, "TC*") -> 5
A9: ID | B9: Test Case Description | C9: Test Case Procedure | D9: Expected Output | H9: Test date | I9: Result | J9: Note
A12: 1. Kiểm tra đăng nhập với mật khẩu chứa khoảng trắng
A13: TC1 | B13: Test case dùng để kiểm thử chức năng Đăng nhập tài khoản người dùng nhập mật khẩu chứa khoảng trắng ' ' | C13: 1: Nhập thông tin tên và email hợp lệ 2: Nhập mật khẩu đúng nhưng có chứa khoảng trắng ' ' ở đầu hoặc cuối mật khẩu 3: Chọn đúng vai trò tài khoản 4: Nhấn nút "Đăng nhập" | D13: Hiển thị cảnh báo lỗi "Email, mật khẩu hoặc vai trò không đúng!" | H13: 21/03/2025 | I13: Pass
A14: 2. Kiểm tra đăng nhập sai mật khẩu nhiều lần
A15: TC2 | B15: Test case dùng để kiểm thử bảo mật chức năng Đăng nhập tài khoản khi người dùng nhập sai mật khẩu nhiều lần | C15: 1: Nhập thông tin tên và email hợp lệ 2: Chọn đúng vai trò người dùng 3: Nhập sai mật khẩu 4: Nhấn nút "Đăng nhập" 5: Lặp lại các bước trên 5 lần | D15: Hiển thị cảnh báo nhập sai mật khẩu nhiều lần, yêu cầu đặt lại mật khẩu hoặc khóa tài khoản X phút | H15: 21/03/2025 | I15: Fail lần 1
H16: 28/03/2025 | I16: Fail lần 2
H17: 45720 | I17: Pass | J17: #VALUE! | K17: Note: Tài khoản bị khóa nhưng trong CSDL vẫn bật active
A18: 3. Kiểm tra quên mật khẩu khi gửi nhiều yêu cầu đặt lại cho 1 email
A19: TC3 | B19: Test case dùng để kiểm thử bảo mật chức năng Đăng nhập tính năng Quên mật khẩu khi gửi nhiều yêu cầu đặt lại trong thời gian ngắn cho 1 email | C19: 1. Chọn tính năng Quên mật khẩu 2. Nhập email hợp lệ có trong hệ thống 3. Nhấn nút "Gửi OTP" 4. Không nhập OTP 5. Lặp lại bước 2 đến 4 thêm 4 lần | D19: Hiển thị cảnh báo "Quá số lần yêu cầu OTP. Hãy thử lại sau X phút." | H19: 28/03/2025 | I19: Fail lần 1 | J19: #VALUE!
H20: 45720 | I20: Pass | J20: #VALUE!
A21: 4. Kiểm tra quên mật khẩu khi dùng mã OTP của phiên khác đặt lại mật khẩu cho phiên này
A22: TC4 | B22: Test case dùng để kiểm thử bảo mật chức năng Đăng nhập tính năng Quên mật khẩu khi dùng mã OTP đã nhận được ở ở lần trước thử cho lần sau | C22: 1. Chọn tính năng Quên mật khẩu 2. Nhập email hợp lệ có trong hệ thống 3. Nhấn nút "Gửi OTP" 4. Không nhập OTP 5. Lặp lại bước 2 đến 4 thêm 1 lần 6. Lấy mã OTP lần nhận đầu tiên nhập cho lần này | D22: Hiển thị cảnh báo lỗi "Mã OTP không chính xác. Vui lòng thử lại." | H22: 28/03/2025 | I22: Pass | J22: #VALUE!
A23: 5. Kiểm tra quên mật khẩu khi dùng mã OTP hết hạn để đổi mật khẩu
A24: TC5 | B24: Test case dùng để kiểm thử bảo mật chức năng Đăng nhập tính năng Quên mật khẩu khi dùng mã OTP hết hạn để đổi mật khẩu. | C24: 1. Chọn tính năng Quên mật khẩu 2. Nhập email hợp lệ có trong hệ thống 3. Nhấn nút "Gửi OTP" 4. Không nhập OTP 5. Chỉnh thời gian sang 24h sau 6. Nhập mã OTP vào hệ thống | D24: Hiển thị cảnh báo lỗi "OTP hết hạn hoặc không hợp lệ." | H24: 45661 | I24: Fail lần 1 | J24: #VALUE!
H25: 25/04/2025 | I25: Pass | J25: #VALUE!

Sheet Module CourseManagement
A1: TEST CASE
A3: System Name： | B3: Course Management System
A4: Module Code： | B4: COURSE - Course Management
A5: Test requirement: | B5: REQ1 - Feature Testing for Course Management
A6: Pass | B6: =COUNTIF(I:I,"Pass") -> 19 | C6: Pending | D6: =COUNTIF(I:I,"Pending") -> 0
A7: Fail | B7: =COUNTIF(I:I,"Fail") -> 8 | C7: Number of test cases: | D7: =COUNTIF(A:A, "TC*") -> 27
A9: ID | B9: Test Case Description | C9: Test Case Procedure | D9: Expected Output | H9: Test date | I9: Result | J9: Note
A11: I. Manage Courses From Admin Site Test
A12: 1. Kiểm tra hệ thống xử lý khi nhập ký tự đặc biệt vào ô “Tên khóa học”
A13: TC1 - Validatate Name Input | B13: Test case dùng để kiểm thử dữ liệu đầu vào của chức năng thêm khóa học khi nhập ký tự đặc biệt vào ô "Tên khóa học" | C13: 1: Mở giao diện Quản lý khóa học chọn "Thêm" 2: Nhập " ##" vào ô "Tên khóa học" 3: Nhập các thông tin khác hợp lệ (có thể chọn hình ảnh hoặc không) 4: Nhấn nút "Thêm" | D13: Hiển thị cảnh báo "Tên khóa học chỉ được chứa chữ cái, số, dấu cách, gạch ngang, gạch dưới hoặc dấu chấm!" | H13: 45995 | I13: Fail lần 1 | J13: #VALUE!
H14: 21/04/2025 | I14: Pass | J14: #VALUE!
A15: 2. Kiểm tra hệ thống xử lý khi nhập ngày không tồn tại vào ô "Ngày bắt đầu" hoặc "Ngày kết thúc"
A16: TC2 - Validate Date Input | B16: Test case dùng để kiểm thử dữ liệu đầu vào của chức năng thêm khóa học khi nhập ngày không tồn tại vào ô "Ngày bắt đầu" hoặc "Ngày kết thúc" | C16: 1: Mở giao diện Quản lý khóa học chọn "Thêm" 2: Chọn "Ngày bắt đầu" hoặc "Ngày kết thúc" là "32/04/2025" 3: Nhập các thông tin khác hợp lệ (có thể chọn hình ảnh hoặc không) 4: Nhấn nút "Thêm" | D16: Hiển thị cảnh báo lỗi không thể thêm khóa học | H16: 45995 | I16: Fail lần 1 | J16: #VALUE!
H17: 21/04/2025 | I17: Pass
A18: 3. Kiểm tra hệ thống xử lý khi chọn file sai định dạng cho mục "Hình ảnh"
A19: TC3 - Validate File Input | B19: Test case dùng để kiểm thử dữ liệu đầu vào của chức năng thêm khóa học khi chọn file sai định dạng cho mục "Hình ảnh" | C19: 1: Mở giao diện Quản lý khóa học chọn "Thêm" 2: Chọn file "New Text Document.txt" có định dạng .txt cho mục hình ảnh 3: Nhập các thông tin khác hợp lệ (có thể chọn hình ảnh hoặc không) 4: Nhấn nút "Thêm" | D19: Hiển thị cảnh báo lỗi không thể thêm khóa học hoặc tự sửa lỗi nhảy về 1 ngày gần nhất hợp lệ | H19: 45995 | I19: Fail lần 1 | J19: #VALUE!
H20: 21/04/2025 | I20: Pass | J20: #VALUE! | K20: Note: nên hiển thị thông báo lỗi và yêu cầu người dùng nhập lại thay vì cơ chế sửa lỗi tự động
A21: 4. Kiểm tra hệ thống xử lý khi nhập sai kiểu dữ liệu vào ô "Học phí"
A22: TC4 - Validate Type Input | B22: Test case dùng để kiểm thử dữ liệu đầu vào của chức năng thêm khóa học khi nhập sai kiểu dữ liệu vào ô "Học phí" | C22: 1: Mở giao diện Quản lý khóa học chọn "Thêm" 2: Nhập "abc" vào ô "Học phí" 3: Nhập các thông tin khác hợp lệ (có thể chọn hình ảnh hoặc không) 4: Nhấn nút "Thêm" | D22: Hiển thị cảnh báo "Học phí phải là một số hợp lệ" | H22: 45995 | I22: Pass | J22: #VALUE!
A23: 5. Kiểm tra quá trình hệ thống xử lý khi thêm một khóa học thành công
A24: TC5 - UI/E2E Test | B24: Test case dùng để kiểm thử end-to-end quá trình thêm khóa học mới vào cơ sở dữ liệu và cách giao diện hiển thị khóa học mới sau khi thêm thành công | C24: 1: Mở giao diện Quản lý khóa học chọn "Thêm" 2: Nhập các giá trị . Tên khóa học: "Khóa học Java" . Giảng viên: "Nguyễn Văn A" . Mô tả: "Khóa học Java" . Ngày bắt đầu: "24/04/2025" . Ngày kết thúc: "01/05/2025" . Học phí: "1000" . Chọn 1 file ảnh bất kì 3: Nhấn nút "Thêm" 4: Sau thông báo thêm thành công kiểm tra cơ sở dữ liệu 5: Kiểm tra lại giao diện | D24: Database lưu khóa học vừa thêm, giao diện hiển thị khóa học mới vừa thêm ("Khóa học Java") ở cuối danh sách với đầy đủ thông tin vừa nhập 1 cách trùng khớp | H24: 21/04/2025 | I24: Fail | J24: #VALUE! | K24: Note: trong cơ sở dữ liệu đã lưu khóa học thành công nhưng giao diện không tự render lại ảnh khóa học, phải đăng xuất đăng nhập lại mới reload
A25: II. Use Courses Modules From Student Site Test
A26: 6. Kiểm tra sự hiển thị của các khóa học có ngày khai giảng >24h
A27: TC6 - Show Courses Function Test | B27: Test case dùng để kiểm thử yêu cầu nghệp vụ chỉ hiện những khóa học >24h trước ngày khai giảng | C27: 1: Setup cơ sở dữ liệu cho các khóa học bắt đầu từ "01/07/2025" 2: Setup thời gian của máy đến ngày "29/06/2025" 3: Truy cập vào tùy chọn "Bảng khóa học" từ giao diện Học viên | D27: Giao diện hiện đầy đủ các khóa học có ngày bắt đầu từ "01/07/2025" | H27: 21/04/2025 | I27: Pass | J27: #VALUE!
A28: 7. Kiểm tra đăng kí thành công khóa học trong vòng 24h trước ngày khai giảng
A29: TC7 - Enroll Course E2E Test | B29: Test case dùng để kiểm thử e2e chức năng đăng kí khóa học thành công ngay trước >24h khi khóa học khai giảng | C29: 1: Setup cơ sở dữ liệu cho 1 khóa học (Java khó) bắt đầu từ ngày 29/04/2025" 2: Đăng nhập bằng tài khoản học viên bất kì 4: Vào tùy chọn "Bảng khóa học" chọn khóa học "Java khó" thêm vào giỏ hàng và thanh toán 5: Vào cơ sở dữ liệu hoặc giao diện Admin để phê duyệt thanh toán 6: Quay lại tài khoản học viên ở bước 2 7: Vào tùy chọn "Khóa học của tôi" | D29: Database lưu trữ khóa học và giao diện hiển thị "Java khó" vừa đăng kí thành công | H29: 27/04/2025 | I29: Pass | J29: #VALUE! | K29: #VALUE!
A30: 8. Kiểm tra sự hiển diện của các khóa học có ngày khai giảng <24h
A31: TC8 - Show Courses Function Test | B31: Test case dùng để kiểm thử yêu cầu nghệp vụ không hiện những khóa học <24h trước ngày khai giảng | C31: 1: Setup cơ sở dữ liệu cho các khóa học bắt đầu từ "01/07/2025" 2: Setup thời gian của máy đến ngày "30/06/2025" 3: Truy cập vào tùy chọn "Bảng khóa học" từ giao diện Học viên | D31: Không hiện bất kì khóa học nào có ngày bắt đầu từ "01/07/2025" | H31: 21/04/2025 | I31: Pass | J31: #VALUE!
A32: 9. Kiểm tra đăng kí khóa học khi khóa học có số học viên đăng kí đủ 40
A33: TC9 - Enroll Course Function Test | B33: Test case dùng để kiểm thử yêu cầu nghiệp vụ khi đăng kí vào khóa học đã có đủ số lượng học viên | C33: 1: Vào NetBeans tạo unit test "testCanEnrollCourse_WhenCourseIsFull()" 2: Dùng mockito giả lập tình huống: Học viên chưa đăng ký khóa học Số lượng học viên hiện tại đã vượt giới hạn cho phép (ví dụ giới hạn là 40, hiện tại là 41) Không bị trùng lịch học 3: Giả lập kết quả trả về là "False" đồng nghĩa việc không đăng kí được 4: Test File | D33: Passed | H33: 26/04/2025 | I33: Pass | J33: #VALUE!
A34: 10. Kiểm tra ràng buộc không cho đăng kí cùng lúc 2 khóa học cùng lịch
A35: TC10 - Enroll Courses Function Test | B35: Test case dùng để kiểm thử yêu cầu nghiệp vụ không cho đăng kí 2 khóa học cùng lịch | C35: 1: Đăng nhập 1 tài khoản học viên bất kì 2: Check cơ sở dữ liệu tìm 2 khóa học trùng lịch 3: Chọn thêm 1 khóa học (Java Web) vào giỏ 4: Chọn thêm 1 khóa học (Java Spring) vào giỏ | D35: Hiển thị thông báo có khóa học trùng lịch không cho thêm vào giỏ | H35: 21/04/2025 | I35: Pass | J35: #VALUE!
A36: 11. Kiểm tra sự hiện diện của các khóa học trùng lịch khi đã đăng kí 1 khóa học trước đó
A37: TC11 - Show Courses Function Test | B37: Test case dùng để kiểm thử yêu cầu nghiệp vụ không cho đăng kí 2 khóa học cùng lịch từ khi đã đăng kí 1 khóa học trước đó trong database | C37: 1: Đăng nhập 1 tài khoản học viên bất kì 2: Check cơ sở dữ liệu tìm 2 khóa học trùng lịch (Java Spring và Java Web) 3: Chọn thêm 1 khóa học (Java Spring) vào giỏ 4: Tiến hành thanh toán 5: Vào cơ sở dữ liệu hoặc giao diện Admin để phê duyệt thanh toán 6: Đăng nhập lại vào tài khoản học viên 7: Chọn filter "Java" | D37: Các khóa học trùng lịch (Java Web) không hiển thị | H37: 21/04/2025 | I37: Pass | J37: #VALUE!
A38: 12. Kiểm tra lỗi khi chọn ngày bắt đầu sau ngày kết thúc
A39: TC12 - Search Courses Function Test | B39: Test case dùng để kiểm thử chức năng filter khóa học khi chọn ngày bắt đầu sau ngày kết thúc | C39: 1: Đăng nhập 1 tài khoản học viên bất kì 2: Chọn "Bảng khóa học" 3: Vào "Lọc khóa học" 4: Chọn ngày bắt đầu sau ngày kết thúc 5: Bấm "Áp dụng bộ lọc" | D39: Hiển thị cảnh báo "Ngày bắt đầu phải trước ngày kết thúc" | H39: 21/04/2025 | I39: Pass | J39: #VALUE!
A40: 13. Kiểm tra hệ thống xử lí khi paste mã độc vào ô tìm kiếm
A41: TC13 - Search Courses Function Test With Malicious Code | B41: Test case dùng để kiểm thử bảo mật chống SQL Injection tìm kiếm khóa học khi nhập mã độc vào ô tìm kiếm | C41: 1: Vào NetBeans tạo unit test "testSQLInjectionInSearch()" 2: Giả lập keyword = "' OR 1=1 --" 3: Dùng Mockito giả lập nhập keyword vào ô tìm kiếm 4: Thiết lập expected output không crash, không lỗi, chỉ không tìm thấy kết quả 5: Test File | D41: Passed | H41: 26/04/2025 | I41: Pass | J41: #VALUE!
A42: 14. Kiểm tra hệ thống xử lí khi paste mã độc vào ô tìm kiếm
A43: TC14 - Search Courses Function Test With Malicious Code | B43: Test case dùng để kiểm thử bảo mật chống XSS tìm kiếm khóa học khi nhập mã độc vào ô tìm kiếm | C43: 1: Vào NetBeans tạo unit test "testXSSInjectionInSearch()" 2: Giả lập keyword = "<script>alert(1)</script>" 3: Dùng Mockito giả lập nhập keyword vào ô tìm kiếm 4: Thiết lập expected output không thực thi câu lệnh hay tìm thấy khóa học 5: Test File | D43: Passed | H43: 26/04/2025 | I43: Pass | J43: #VALUE!
...

Sheet Module FeeManagement
A1: TEST CASE
A3: System Name： | B3: Course Management System
A4: Module Code： | B4: FEE - Fee Management
A5: Test requirement: | B5: REQ1 - Feature Testing for Fee Management
A6: Pass | B6: =COUNTIF(I:I,"Pass") -> 5 | C6: Pending | D6: =COUNTIF(I:I,"Pending") -> 0
A7: Fail | B7: =COUNTIF(I:I,"Fail") -> 0 | C7: Number of test cases: | D7: =COUNTIF(A:A, "TC*") -> 5
A9: ID | B9: Test Case Description | C9: Test Case Procedure | D9: Expected Output | H9: Test date | I9: Result | J9: Note
A12: 1. Kiểm tra tính năng giảm giá khi đăng kí <3 khóa học
A13: TC1 - Discount Function Test | B13: Test case dùng để kiểm thử yêu cầu nghiệp vụ chỉ giảm giá cho học viên đăng kí từ 3 khóa học khi cùng lúc đăng kí 2 khóa học | C13: 1: Đăng nhập với tài khoản học viên bất kì 2: Chọn 2 khóa học bất kì 3: Bấm nút thanh toán | D13: Giao diện hiển thị đúng giá gốc học phí | H13: 21/04/2025 | I13: Pass | J13: #VALUE! | K13: Note: nên hiện thông báo "Đăng kí thêm 1 khóa học để được giảm X%" thay vì báo chưa đủ khóa học để giảm giá
A14: 2. Kiểm tra tính năng giảm giá khi đăng kí từ 3 khóa học
A15: TC2 - Discount Function Test | B15: Test case dùng để kiểm thử yêu cầu nghiệp vụ chỉ giảm giá cho học viên đăng kí từ 3 khóa học khi cùng lúc đăng kí 3 khóa học | C15: 1: Đăng nhập với tài khoản học viên bất kì 2: Chọn 3 khóa học bất kì 3: Bấm nút thanh toán | D15: Giao diện hiển thị giá học phí và thông báo giảm X% khi đăng kí từ 3 khóa học | H15: 21/04/2025 | I15: Pass | J15: #VALUE!
A16: 3. Kiểm tra tính năng hoàn tiền trong 7 ngày kể từ ngày đăng kí
A17: TC3 - Refund E2E Test | B17: Test case dùng để kiểm thử e2e yêu cầu nghiệp vụ hoàn tiền trong 7 ngày kể từ ngày thanh toán | C17: 1: Đăng nhập với tài khoản học viên bất kì 2: Chọn 1 khóa học (Java siêu khó) 3: Thanh toán 4: Vào giao diện Admin hoặc databse phê duyệt thanh toán 5: Setup thời gian đến ngày "03/05/2025" -> 7 ngày kể từ ngày phê duyệt 5: Quay trở lại tài khoản học viên ở bước 1 6: Vào "Khóa học của tôi" 7: Chọn khóa học Java siêu khó và bấm Hoàn tiền 8: Vào database kiểm tra trạng thái 9: Quay trở lại giao diện học viên bấm vào "Khóa học của tôi" | D17: . Hiện thông báo phê duyệt hoàn tiền thành công . Database đổi trạng thái thành Cancelled . Giao diện không hiển thị khóa học | H17: 26/04/2025 | I17: Pass | J17: #VALUE!
A18: 4. Kiểm tra tính năng hoàn tiền >7 ngày kể từ ngày đăng kí
A19: TC4 - Refund Function Test | B19: Test case dùng để kiểm thử yêu cầu nghiệp vụ hoàn tiền quá 7 ngày kể từ ngày thanh toán | C19: 1: Đăng nhập với tài khoản học viên bất kì 2: Chọn 1 khóa học (Java siêu khó) 3: Thanh toán 4: Vào giao diện Admin hoặc databse phê duyệt thanh toán 5: Setup thời gian đến ngày "04/05/2025" -> 8 ngày kể từ ngày phê duyệt 5: Quay trở lại tài khoản học viên ở bước 1 6: Vào "Khóa học của tôi" 7: Chọn khóa học Java siêu khó và bấm Hoàn tiền | D19: Hiện thông báo hoàn tiền không thành công vì quá hạn | H19: 26/04/2025 | I19: Pass | J19: #VALUE!
A20: 5. Kiểm tra tính năng hoàn tiền trong 7 ngày kể từ ngày đăng kí nhưng đã qua ngày khai giảng khóa học
A21: TC5 - Refund Function Test | B21: Test case dùng để kiểm thử chức năng hoàn tiền trong 7 ngày kể từ ngày thanh toán nhưng khóa học đã bắt đầu | C21: 1: Đăng nhập với tài khoản học viên bất kì 2: Chọn 1 khóa học (Khoa học Dữ liệu 1) 3: Thanh toán 4: Vào giao diện Admin hoặc databse phê duyệt thanh toán 5: Setup thời gian đến ngày "03/05/2025" -> 7 ngày kể từ ngày phê duyệt 6: Vào database chỉnh thời gian khóa học bắt đầu thành "02/05/2025" 7: Quay trở lại tài khoản học viên ở bước 1 8: Vào "Khóa học của tôi" 9: Chọn khóa Khoa học Dữ liệu 1 bấm Hoàn tiền | D21: Hiện thông báo cho phép hoàn tiền | H21: 27/04/2025 | I21: Pass | J21: #VALUE! | K21: Note: nên hiển thị cửa sổ cho người dùng "Xác nhận" xem có chắc chắn rút khỏi khóa học hay không

Sheet Module Admin
A1: TEST CASE
A3: System Name： | B3: Course Management System
A4: Module Code： | B4: ADMIN - Administration Module
A5: Test requirement: | B5: REQ0 - Feature Testing for Admin
A6: Pass | B6: =COUNTIF(I:I,"Pass") -> 0 | C6: Pending | D6: =COUNTIF(I:I,"Pending") -> 0
A7: Fail | B7: =COUNTIF(I:I,"Fail") -> 5 | C7: Number of test cases: | D7: =COUNTIF(A:A, "TC*") -> 5
A9: ID | B9: Test Case Description | C9: Test Case Procedure | D9: Expected Output | H9: Test date | I9: Result | J9: Note
A13: TC1 - User Session Security Test | B13: Test case dùng để kiểm thử bảo mật việc xóa tài khoản khi đang đăng nhập có hủy phiên làm việc không | C13: 1: Mở giao diện Quản lý Người dùng 2: Chọn tài khoản admin đang trong phiên đăng nhập nhấn "Xóa" 3: Kiểm tra cơ sở dữ liệu sau thông báo đã xóa 4: Đợi tầm 10s và click các tùy chọn | D13: Phiên đăng nhập của tài khoản bị vô hiệu hóa ngay lập tức, khi thao tác sẽ thoát ra màn hình đăng nhập | H13: 21/04/2025 | I13: Fail | J13: #VALUE!
A15: TC2 - User Session Security Test | B15: Test case dùng để kiểm thử bảo mật kéo theo từ TC1 việc tài khoản bị xóa thực hiện thao tác tiếp với hệ thống | C15: 1: Mở giao diện Quản lý Người dùng 2: Chọn tài khoản admin đang trong phiên đăng nhập nhấn "Xóa" 3: Kiểm tra cơ sở dữ liệu sau thông báo đã xóa 4: Sử dụng tài khoản hiện tại truy cập Quản lý thanh toán 5: Chọn và xóa 1 trong những thanh toán đã lưu | D15: Phiên đăng nhập của tài khoản bị vô hiệu hóa ngay lập tức, khi thao tác sẽ thoát ra màn hình đăng nhập | H15: 21/04/2025 | I15: Fail | J15: #VALUE!
A17: TC3 - User Account Security Test | B17: Test case dùng để kiểm thử bảo mật việc đăng nhập bằng tài khoản bị khóa từ admin dashboard | C17: 1: Mở giao diện Quản lý Người dùng 2: Chọn tài khoản "Nhật Nguyễn" bấm "Bật/Tắt tài khoản" 3: Kiểm tra cơ sở dữ liệu sau thông báo đã tắt 4: Đăng xuất 5: Đăng nhập lại vào tài khoản "Nhật Nguyễn" | D17: Hiển thị thông báo tài khoản đã bị khóa và thông tin liên hệ mở tài khoản | H17: 21/04/2025 | I17: Fail | J17: #VALUE!
A19: TC4 - User Account Security Test | B19: Test case dùng để kiểm thử bảo mật kéo theo từ TC2 việc dùng tài khoản bị khóa thực hiện những thao tác trên app | C19: 1: Mở giao diện Quản lý Người dùng 2: Chọn tài khoản "Nhật Nguyễn" bấm "Bật/Tắt tài khoản" 3: Kiểm tra cơ sở dữ liệu sau thông báo đã tắt 4: Đăng xuất 5: Đăng nhập lại vào tài khoản "Nhật Nguyễn" 6: Thêm 1 khóa học bất kì vào giỏ | D19: Hiển thị thông báo tài khoản đã bị khóa và thông tin liên hệ mở tài khoản đồng thời không cho thực hiện thao tác | H19: 21/04/2025 | I19: Fail | J19: #VALUE!
A21: TC5 - UI/E2E Test | B21: Test case dùng để kiểm thử end-to-end quá trình tắt active các khóa học, cập nhật cơ sở dữ liệu và kết quả hiển thị trên giao diện | C21: 1: Mở giao diện Quản lý khóa học 2: Chọn các khóa học và bấm "Bật/Tắt khóa học" đến khi chỉ còn 3 khóa học đang hoạt động 3: Kiểm tra cơ sở dữ liệu đã tắt thành công chưa 4: Kiểm tra giao diện hiển thị khóa học sau khi đã tắt hầu hết khóa học | D21: Các khóa học đã tắt thành công trong cơ sở dữ liệu và giao diện hiển thị các khóa học đang hoạt động ở trên - các khóa học đã tắt ở dưới hoặc ở một nơi khác | H21: 21/04/2025 | I21: Fail | J21: #VALUE! | K21: Note: các khóa học đã tắt không hiển thị => không thể bật từ giao diện mà phải bật ở cơ sở dữ liệu Note: Không thể chọn nhiều khóa học để thao tác cùng lúc mà phải tắt từng cái

Sheet Test Report
A1: TEST REPORT
B3: Note:
B4: Date | C4: 27/04/2025
B7: No | C7: Module code | D7: Pass | E7: Fail | F7: Pending | G7: Number of test cases
B8: 1 | C8: ='Module Register'!B4 -> REG - User Registration | D8: ='Module Register'!B6 -> 4 | E8: ='Module Register'!B7 -> 0 | F8: ='Module Register'!D6 -> 0 | G8: ='Module Register'!D7 -> 4
B9: 2 | C9: ='Module Login'!B4 -> AUTH - User Login | D9: ='Module Login'!B6 -> 5 | E9: ='Module Login'!B7 -> 0 | F9: ='Module Login'!D6 -> 0 | G9: ='Module Login'!D7 -> 5
B10: 3 | C10: ='Module CourseManagement'!B4 -> COURSE - Course Management | D10: ='Module CourseManagement'!B6 -> 19 | E10: ='Module CourseManagement'!B7 -> 8 | F10: ='Module CourseManagement'!D6 -> 0 | G10: ='Module CourseManagement'!D7 -> 27
B11: 4 | C11: ='Module FeeManagement'!B4 -> FEE - Fee Management | D11: ='Module FeeManagement'!B6 -> 5 | E11: ='Module FeeManagement'!B7 -> 0 | F11: ='Module FeeManagement'!D6 -> 0 | G11: ='Module FeeManagement'!D7 -> 5
B12: 5 | C12: ='Module Admin'!B4 -> ADMIN - Administration Module | D12: ='Module Admin'!B6 -> 0 | E12: ='Module Admin'!B7 -> 5 | F12: ='Module Admin'!D6 -> 0 | G12: ='Module Admin'!D7 -> 5
C13: Sub total | D13: =SUM(D6:D12) -> 33 | E13: =SUM(E6:E12) -> 13 | F13: =SUM(F6:F12) -> 0 | G13: =SUM(G6:G12) -> 46
C15: Test coverage | E15: =(D13+E13)*100/G13 -> 100 | F15: %
C16: Test successful coverage | E16: =D13*100/G13 -> 71.73913 | F16: %
